<?xml version="1.0" encoding="utf-8"?>
<!-- This URDF was automatically created by SolidWorks to URDF Exporter! Originally created by Stephen Brawner (brawner@gmail.com) 
     Commit Version: 1.6.0-1-g15f4949  Build Version: 1.6.7594.29634
     For more information, please see http://wiki.ros.org/sw_urdf_exporter -->

<robot name="Art">

  <gazebo>
    <plugin name="gazebo_ros_control" filename="libgazebo_ros_control.so">
      <robotNamespace>/Art</robotNamespace>
    </plugin>
  </gazebo>
   
  <link name="base_link">
    <inertial>
      <origin xyz="-0.037566 0.013859 0.4427" rpy="0 0 0" />
      <mass value="5.0" />
      <inertia ixx="0.61955" ixy="-0.020552" ixz="0.039836" iyy="0.72755" iyz="-0.056061" izz="0.49855" />
    </inertial>
    <visual>
      <origin xyz="0 0 0" rpy="0 0 0" />
      <geometry>
        <mesh filename="package://artpark/meshes/base_link.STL" />
      </geometry>
      <material name="">
        <color rgba="0.75294 0.75294 0.75294 1" />
      </material>
    </visual>
    <collision>
      <origin xyz="0 0 0" rpy="0 0 0" />
      <geometry>
        <mesh filename="package://artpark/meshes/base_link.STL" />
      </geometry>
    </collision>
  </link>

  <gazebo reference="base_link">
        <kp>1000.0</kp>
        <kd>1000.0</kd>
        <mu1>0.0</mu1>
        <mu2>0.0</mu2>
        <material>Gazebo/Grey</material>
  </gazebo>
  
  <link name="link_wheel1">
    <inertial>
      <origin xyz="1.1102E-16 0.0255 -1.1102E-16" rpy="0 0 0" />
      <mass value="0.3" />
      <inertia ixx="0.0014524" ixy="-3.8688E-19" ixz="1.4813E-19" iyy="0.0025728" iyz="-3.6562E-19" izz="0.0014524" />
    </inertial>
    <visual>
      <origin xyz="0 0 0" rpy="0 0 0" />
      <geometry>
        <mesh filename="package://artpark/meshes/link_wheel1.STL" />
      </geometry>
      <material name="">
        <color rgba="0.75294 0.75294 0.75294 1" />
      </material>
    </visual>
    <collision>
      <origin xyz="0 0 0" rpy="0 0 0" />
      <geometry>
        <mesh filename="package://artpark/meshes/link_wheel1.STL" />
      </geometry>
    </collision>
  </link>


  <joint name="joint_wheel1" type="continuous">
    <origin xyz="0 -0.2568 -0.07326" rpy="0 0 0" />
    <parent link="base_link" />
    <child link="link_wheel1" />
    <axis xyz="0 1 0" />
    <joint_properties damping="1.0" friction="1.0" />
    <limit effort="20" velocity="15"/>
  </joint>

  <gazebo reference="link_wheel1">
      <kp>10000000.0</kp>
      <kd>0.1</kd>
      <mu1>200.0</mu1>
      <mu2>100.0</mu2>
      <material>Gazebo/Blue</material>
  </gazebo>

  <link name="link_wheel2">
    <inertial>
      <origin xyz="0 0.0255 0" rpy="0 0 0" />
      <mass value="0.3" />
      <inertia ixx="0.0014524" ixy="-3.8688E-19" ixz="1.4813E-19" iyy="0.0025728" iyz="-3.6562E-19" izz="0.0014524" />
    </inertial>
    <visual>
      <origin xyz="0 0 0" rpy="0 0 0" />
      <geometry>
        <mesh filename="package://artpark/meshes/link_wheel2.STL" />
      </geometry>
      <material name="">
        <color rgba="0.75294 0.75294 0.75294 1" />
      </material>
    </visual>
    <collision>
      <origin xyz="0 0 0" rpy="0 0 0" />
      <geometry>
        <mesh filename="package://artpark/meshes/link_wheel2.STL" />
      </geometry>
    </collision>
  </link>


  <joint name="joint_wheel2" type="continuous">
    <origin xyz="0 0.2058 -0.07326" rpy="0 0 0" />
    <parent link="base_link" />
    <child link="link_wheel2" />
    <axis xyz="0 1 0" />
    <joint_properties damping="1.0" friction="1.0" />
    <limit effort="20" velocity="15"/>
  </joint>

  <gazebo reference="link_wheel2">
      <kp>10000000.0</kp>
      <kd>0.1</kd>
      <mu1>200.0</mu1>
      <mu2>100.0</mu2>
      <material>Gazebo/Blue</material>
  </gazebo>

  <link name="link_sweeper">
    <inertial>
      <origin xyz="-0.118974812224288 -0.00569987819571294 0.62703959498131" rpy="0 0 0" />
      <mass value="0.1" />
      <inertia ixx="0.0217266121738267" ixy="-1.11981627703815E-05" ixz="-0.000422883505219814"  iyy="0.0240866757433668" iyz="-2.74404247659959E-05" izz="0.00292483559843762" />
    </inertial>
    <visual>
      <origin xyz="0 0 0" rpy="0 0 0" />
      <geometry>
        <mesh filename="package://artpark/meshes/link_sweeper.STL" />
      </geometry>
      <material name="">
        <color rgba="0.752941176470588 0.752941176470588 0.752941176470588 1" />
      </material>
    </visual>
    <collision>
      <origin xyz="0 0 0" rpy="0 0 0" />
      <geometry>
        <mesh filename="package://artpark/meshes/link_sweeper.STL" />
      </geometry>
    </collision>
  </link>


  <joint name="joint_sweeper" type="revolute">
    <origin xyz="0.44159 0 -0.0627" rpy="0 0 0" />
    <parent link="base_link" />
    <child link="link_sweeper" />
    <axis xyz="-1 0 0" />
    <limit lower="-3.14" upper="3.14" effort="10" velocity="5" />
  </joint>

  <gazebo reference="link_sweeper">
        <kp>1000.0</kp>
        <kd>1000.0</kd>
        <mu1>10.0</mu1>
        <mu2>10.0</mu2>
        <material>Gazebo/Black</material>
  </gazebo>

  <link name="link_foam">
    <inertial>
      <origin xyz="0.00270261873313471 0.510664588823056 0.034603922413234" rpy="0 0 0" />
      <mass value="0.05" />
      <inertia ixx="0.373827181818088" ixy="-0.000110501116816829" ixz="0.00303185397530584" iyy="0.107364626536446" iyz="-0.00141483962411224" izz="0.412409790185553" />
    </inertial>
    <visual>
      <origin xyz="0 0 0" rpy="0 0 0" />
      <geometry>
        <mesh filename="package://artpark/meshes/link_foam.STL" />
      </geometry>
      <material name="">
        <color rgba="0.752941176470588 0.752941176470588 0.752941176470588 1" />
      </material>
    </visual>
    <collision>
      <origin xyz="0 0 0" rpy="0 0 0" />
      <geometry>
        <mesh filename="package://artpark/meshes/link_foam.STL" />
      </geometry>
    </collision>
  </link>


  <joint name="joint_foam" type="revolute">
    <origin xyz="-0.1319 -0.0823 0.88394" rpy="0 0 0" />
    <parent link="base_link" />
    <child link="link_foam" />
    <axis xyz="0 1 0" />
    <limit lower="-3.14" upper="3.14" effort="10" velocity="5" />
  </joint>

  <gazebo reference="link_foam">
        <kp>1000.0</kp>
        <kd>1000.0</kd>
        <mu1>10.0</mu1>
        <mu2>10.0</mu2>
        <material>Gazebo/Yellow</material>
  </gazebo>

  <link name="link_gripper">
    <inertial>
      <origin xyz="-0.0868812536550505 0.162184291079733 -0.21099322010557" rpy="0 0 0" />
      <mass value="0.05" />
      <inertia ixx="0.0057537606945618" ixy="-9.98774651786145E-06" ixz="3.34084840002639E-05" iyy="0.0058025799979368" iyz="0.00172529643458475" izz="0.00264012204998806" />
    </inertial>
    <visual>
      <origin xyz="0 0 0" rpy="0 0 0" />
      <geometry>
        <mesh filename="package://artpark/meshes/link_gripper.STL" />
      </geometry>
      <material name="">
        <color rgba="0.752941176470588 0.752941176470588 0.752941176470588 1" />
      </material>
    </visual>
    <collision>
      <origin xyz="0 0 0" rpy="0 0 0" />
      <geometry>
        <mesh filename="package://artpark/meshes/link_gripper.STL" />
      </geometry>
    </collision>
  </link>


  <joint name="joint_gripper" type="revolute">
    <origin xyz="0.0854 0.17714 0.24335" rpy="0 0 0" />
    <parent link="base_link" />
    <child link="link_gripper" />
    <axis xyz="-1 0 0" />
    <limit lower="-3.14" upper="3.14" effort="10" velocity="5" />
  </joint>

  <gazebo reference="link_gripper">
        <kp>1000.0</kp>
        <kd>1000.0</kd>
        <mu1>10.0</mu1>
        <mu2>10.0</mu2>
        <material>Gazebo/Red</material>
  </gazebo>

  <link name="link_gear_left">
    <inertial>
      <origin xyz="0.029535 0.080378 -0.047822" rpy="0 0 0" />
      <mass value="0.02" />
      <inertia ixx="0.00057128" ixy="-7.6781E-06" ixz="-4.529E-05" iyy="0.00032232" iyz="0.00011039" izz="0.0005149" />
    </inertial>
    <visual>
      <origin xyz="0 0 0" rpy="0 0 0" />
      <geometry>
        <mesh filename="package://artpark/meshes/link_gear_left.STL" />
      </geometry>
      <material name="">
        <color rgba="0.75294 0.75294 0.75294 1" />
      </material>
    </visual>
    <collision>
      <origin xyz="0 0 0" rpy="0 0 0" />
      <geometry>
        <mesh filename="package://artpark/meshes/link_gear_left.STL" />
      </geometry>
    </collision>
  </link>


  <joint name="joint_gear_left" type="revolute">
    <origin xyz="-0.05869 0.25731 -0.28611" rpy="0 0 0" />
    <parent link="link_gripper" />
    <child link="link_gear_left" />
    <axis xyz="0 0.99893 0.046337" />
    <limit lower="-3.14" upper="3.14" effort="10" velocity="5" />
  </joint>

  <gazebo reference="link_gear_left">
        <kp>1000.0</kp>
        <kd>1000.0</kd>
        <mu1>10.0</mu1>
        <mu2>10.0</mu2>
        <material>Gazebo/Orange</material>
  </gazebo>

  <link name="link_gear_right">
    <inertial>
      <origin xyz="-0.02981 0.080304 -0.047658" rpy="0 0 0" />
      <mass value="0.02" />
      <inertia ixx="0.00057203" ixy="8.4073E-06"  ixz="4.4904E-05"  iyy="0.00032244"  iyz="0.00011047"  izz="0.00051462" />
    </inertial>
    <visual>
      <origin xyz="0 0 0" rpy="0 0 0" />
      <geometry>
        <mesh filename="package://artpark/meshes/link_gear_right.STL" />
      </geometry>
      <material name="">
        <color rgba="0.75294 0.75294 0.75294 1" />
      </material>
    </visual>
    <collision>
      <origin xyz="0 0 0" rpy="0 0 0" />
      <geometry>
        <mesh filename="package://artpark/meshes/link_gear_right.STL" />
      </geometry>
    </collision>
  </link>


  <joint name="joint_gear_right" type="revolute">
    <origin xyz="-0.112110130655963 0.257365431419489 -0.286111697251884" rpy="0 0 0" />
    <parent link="link_gripper" />
    <child link="link_gear_right" />
    <axis xyz="0 0.998925867461397 0.0463369325322188" />
    <limit lower="-3.14" upper="3.14" effort="10" velocity="5" />
  </joint>

  <gazebo reference="link_gear_right">
        <kp>1000.0</kp>
        <kd>1000.0</kd>
        <mu1>10.0</mu1>
        <mu2>10.0</mu2>
        <material>Gazebo/Orange</material>
  </gazebo>

    <link name="link_servo_gripper">
    <inertial>
      <origin xyz="0.0056935 -0.0001808 0.044811" rpy="0 0 0" />
      <mass value="0.005" />
      <inertia ixx="4.9306E-05" ixy="-1.6278E-09" ixz="-8.4092E-07" iyy="4.8314E-05" iyz="1.9885E-08" izz="2.0275E-05" />
    </inertial>
    <visual>
      <origin xyz="0 0 0" rpy="0 0 0" />
      <geometry>
        <mesh filename="package://artpark/meshes/link_servo_gripper.STL" />
      </geometry>
      <material name="">
        <color rgba="0.75294 0.75294 0.75294 1" />
      </material>
    </visual>
    <collision>
      <origin xyz="0 0 0" rpy="0 0 0" />
      <geometry>
        <mesh filename="package://artpark/meshes/link_servo_gripper.STL" />
      </geometry>
    </collision>
  </link>


  <joint name="joint_servo_gripper" type="revolute">
    <origin xyz="0.08 0.5373 0.9285" rpy="0 0 0" />
    <parent link="base_link" />
    <child link="link_servo_gripper" />
    <axis xyz="0 0 -1" />
    <limit lower="-3.14" upper="3.14" effort="10" velocity="5" />
  </joint>

  <gazebo reference="link_servo_gripper">
        <kp>1000</kp>
        <kd>1000</kd>
        <mu1>0.0</mu1>
        <mu2>0.0</mu2>
        <material>Gazebo/White</material>
  </gazebo>

  <link name="link_gripper_left">
    <inertial>
      <origin xyz="0.039765 -0.021066 0.0066152" rpy="0 0 0" />
      <mass value="0.002" />
      <inertia ixx="9.4935E-07" ixy="1.6743E-06" ixz="-3.3323E-08" iyy="5.2839E-06" iyz="1.6234E-08" izz="6.0992E-06" />
    </inertial>
    <visual>
      <origin xyz="0 0 0" rpy="0 0 0" />
      <geometry>
        <mesh filename="package://artpark/meshes/link_gripper_left.STL" />
      </geometry>
      <material name="">
        <color rgba="0.75294 0.75294 0.75294 1" />
      </material>
    </visual>
    <collision>
      <origin xyz="0 0 0" rpy="0 0 0" />
      <geometry>
        <mesh filename="package://artpark/meshes/link_gripper_left.STL" />
      </geometry>
    </collision>
  </link>


  <joint name="joint_gripper_left" type="revolute">
    <origin xyz="0.0560000000000215 -0.00873501320112924 0.0362767948396809" rpy="0 0 0" />
    <parent link="link_servo_gripper" />
    <child link="link_gripper_left" />
    <axis xyz="0 -0.0198992999000344 -0.999801989327631" />
    <limit lower="-3.14" upper="3.14" effort="10" velocity="5" />
  </joint>

  <gazebo reference="link_gripper_left">
        <kp>1000</kp>
        <kd>1000</kd>
        <mu1>10.0</mu1>
        <mu2>10.0</mu2>
        <material>Gazebo/Black</material>
  </gazebo>

  <link name="link_gripper_right">
    <inertial>
      <origin xyz="0.043814 0.022018 0.0059238" rpy="0 0 0" />
      <mass value="0.002" />
      <inertia ixx="9.3617E-07" ixy="-1.7441E-06" ixz="3.4713E-08" iyy="4.7626E-06" iyz="1.6046E-08" izz="5.5684E-06" />
    </inertial>
    <visual>
      <origin xyz="0 0 0" rpy="0 0 0" />
      <geometry>
        <mesh filename="package://artpark/meshes/link_gripper_right.STL" />
      </geometry>
      <material name="">
        <color rgba="0.75294 0.75294 0.75294 1" />
      </material>
    </visual>
    <collision>
      <origin xyz="0 0 0" rpy="0 0 0" />
      <geometry>
        <mesh filename="package://artpark/meshes/link_gripper_right.STL" />
      </geometry>
    </collision>
  </link>


  <joint name="joint_gripper_right" type="revolute">
    <origin xyz="0.0560000000000211 0.00825831588544101 0.0357724668483028" rpy="0 0 0" />
    <parent link="link_servo_gripper" />
    <child link="link_gripper_right" />
    <axis xyz="0 -0.0198992999000344 -0.999801989327631" />
    <limit lower="-3.14" upper="3.14" effort="10" velocity="5" />
  </joint>

  <gazebo reference="link_gripper_right">
        <kp>1000</kp>
        <kd>1000</kd>
        <mu1>10.0</mu1>
        <mu2>10.0</mu2>
        <material>Gazebo/Black</material>
  </gazebo>

  <link name="link_flap">
    <inertial>
      <origin xyz="0 0 0" rpy="0 0 0" />
      <mass value="0.1" />
      <inertia ixx="0.00307344876705749" ixy="-7.24382576491878E-18" ixz="-1.11494946847084E-17" iyy="0.0014364237928572" iyz="8.39790047162671E-05" izz="0.00163830509110542" />
    </inertial>
    <visual>
      <origin xyz="0 0 0" rpy="0 0 0" />
      <geometry>
        <mesh filename="package://artpark/meshes/link_flap.STL" />
      </geometry>
      <material name="">
        <color rgba="0.75294 0.75294 0.75294 1" />
      </material>
    </visual>
    <collision>
      <origin xyz="0 0 0" rpy="0 0 0" />
      <geometry>
        <mesh filename="package://artpark/meshes/link_flap.STL" />
      </geometry>
    </collision>
  </link>


  <joint name="joint_flap" type="revolute">
    <origin xyz="0.2373 -0.0331 0.4403" rpy="0 -0.00061058 0" />
    <parent link="base_link" />
    <child link="link_flap" />
    <axis xyz="0 -1 0" />
    <limit lower="-3.14" upper="3.14" effort="10" velocity="5" />
  </joint> 

  <gazebo reference="link_flap">
        <kp>1000.0</kp>
        <kd>1000.0</kd>
        <mu1>10.0</mu1>
        <mu2>10.0</mu2>
        <material>Gazebo/Green</material>
  </gazebo> 


<!-- - - - - - - - - - -  - Sensor - - - - - - - - - - - -->

  <link name="sensor_laser">
    <inertial>
      <origin xyz="0.01 0 0.01" rpy="0 0 0" />
      <mass value="0.01" />
      <inertia ixx="0.00145" ixy="0" ixz="0" iyy="0.00145" iyz="0" izz="0.00125"/>
    </inertial>

    <visual>
      <origin xyz="0.01 0 0.01" rpy="0 0 0" />
      <geometry>
        <cylinder radius="0.05" length="0.1"/>
      </geometry>
      <material name="red"/>
    </visual>

    <collision>
      <origin xyz="0.01 0 0.01" rpy="0 0 0"/>
      <geometry>
        <cylinder radius="0.05" length="0.1"/>
      </geometry>
    </collision>
  </link>
   
  <joint name="joint_sensor_laser" type="fixed">
    <origin xyz="-0.24 0 0.27" rpy="0 0 -3.14"/>
    <parent link="base_link"/>
    <child link="sensor_laser"/>
  </joint>

  <gazebo reference="sensor_laser">
        <kp>1000.0</kp>
        <kd>1000.0</kd>
        <mu1>10.0</mu1>
        <mu2>10.0</mu2>
        <material>Gazebo/Red</material>
  </gazebo>

  <gazebo reference="sensor_laser">
    <sensor type="ray" name="head_hokuyo_sensor">
      <pose>-10 0 0 0 0 0</pose>
      <visualize>true</visualize>
      <update_rate>20</update_rate>
      <ray>
        <scan>
          <horizontal>
            <samples>720</samples>
            <resolution>1</resolution>
            <min_angle>-1.570796</min_angle>
            <max_angle>1.570796</max_angle>
          </horizontal>
        </scan>
        <range>
          <min>0.10</min>
          <max>10.0</max>
          <resolution>0.01</resolution>
        </range>
        <noise>
          <type>gaussian</type>
          <mean>0.0</mean>
          <stddev>0.01</stddev>
        </noise>
      </ray>
      <plugin name="gazebo_ros_head_hokuyo_controller" filename="libgazebo_ros_laser.so">
        <topicName>/Art/laser/scan</topicName>
        <frameName>sensor_laser</frameName>
      </plugin>
    </sensor>
  </gazebo>

<!-- - - - - - - - - - - - - - - Transmissions - - - - - - - - - - - - - - - - - - - -->

  <transmission name="tran1">
    <type>transmission_interface/SimpleTransmission</type>
    <joint name="joint_sweeper">
      <hardwareInterface>hardware_interface/EffortJointInterface</hardwareInterface>
    </joint>
    <actuator name="motor1">
      <mechanicalReduction>1</mechanicalReduction>
      <hardwareInterface>hardware_interface/EffortJointInterface</hardwareInterface>
    </actuator>
  </transmission>

  <transmission name="tran2">
    <type>transmission_interface/SimpleTransmission</type>
    <joint name="joint_foam">
      <hardwareInterface>hardware_interface/EffortJointInterface</hardwareInterface>
    </joint>
    <actuator name="motor2">
      <mechanicalReduction>1</mechanicalReduction>
      <hardwareInterface>hardware_interface/EffortJointInterface</hardwareInterface>
    </actuator>
  </transmission>

  <transmission name="tran3">
    <type>transmission_interface/SimpleTransmission</type>
    <joint name="joint_servo_gripper">
      <hardwareInterface>hardware_interface/VelocityJointInterface</hardwareInterface>
    </joint>
    <actuator name="motor3">
      <mechanicalReduction>1</mechanicalReduction>
      <hardwareInterface>hardware_interface/VelocityJointInterface</hardwareInterface>
    </actuator>
  </transmission>

  
  <transmission name="tran4">
    <type>transmission_interface/SimpleTransmission</type>
    <joint name="joint_gripper">
      <hardwareInterface>hardware_interface/EffortJointInterface</hardwareInterface>
    </joint>
    <actuator name="motor4">
      <mechanicalReduction>1</mechanicalReduction>
      <hardwareInterface>hardware_interface/EffortJointInterface</hardwareInterface>
    </actuator>
  </transmission>

  <transmission name="tran5">
    <type>transmission_interface/SimpleTransmission</type>
    <joint name="joint_flap">
      <hardwareInterface>hardware_interface/EffortJointInterface</hardwareInterface>
    </joint>
    <actuator name="motor5">
      <mechanicalReduction>1</mechanicalReduction>
      <hardwareInterface>hardware_interface/EffortJointInterface</hardwareInterface>
    </actuator>
  </transmission>

  <transmission name="tran6">
    <type>transmission_interface/SimpleTransmission</type>
    <joint name="joint_wheel1">
      <hardwareInterface>hardware_interface/VelocityJointInterface</hardwareInterface>
    </joint>
    <actuator name="motor6">
      <mechanicalReduction>1</mechanicalReduction>
      <hardwareInterface>hardware_interface/VelocityJointInterface</hardwareInterface>
    </actuator>
  </transmission>

  <transmission name="tran7">
    <type>transmission_interface/SimpleTransmission</type>
    <joint name="joint_wheel2">
      <hardwareInterface>hardware_interface/VelocityJointInterface</hardwareInterface>
    </joint>
    <actuator name="motor7">
      <mechanicalReduction>1</mechanicalReduction>
      <hardwareInterface>hardware_interface/VelocityJointInterface</hardwareInterface>
    </actuator>
  </transmission>

  <transmission name="tran8">
    <type>transmission_interface/SimpleTransmission</type>
    <joint name="joint_gripper_left">
      <hardwareInterface>hardware_interface/VelocityJointInterface</hardwareInterface>
    </joint>
    <actuator name="motor8">
      <mechanicalReduction>1</mechanicalReduction>
      <hardwareInterface>hardware_interface/VelocityJointInterface</hardwareInterface>
    </actuator>
  </transmission>

  <transmission name="tran9">
    <type>transmission_interface/SimpleTransmission</type>
    <joint name="joint_gripper_right">
      <hardwareInterface>hardware_interface/VelocityJointInterface</hardwareInterface>
    </joint>
    <actuator name="motor9">
      <mechanicalReduction>1</mechanicalReduction>
      <hardwareInterface>hardware_interface/VelocityJointInterface</hardwareInterface>
    </actuator>
  </transmission>

  <transmission name="tran10">
    <type>transmission_interface/SimpleTransmission</type>
    <joint name="joint_gear_left">
      <hardwareInterface>hardware_interface/EffortJointInterface</hardwareInterface>
    </joint>
    <actuator name="motor10">
      <mechanicalReduction>1</mechanicalReduction>
      <hardwareInterface>hardware_interface/EffortJointInterface</hardwareInterface>
    </actuator>
  </transmission>

  <transmission name="tran11">
    <type>transmission_interface/SimpleTransmission</type>
    <joint name="joint_gear_right">
      <hardwareInterface>hardware_interface/EffortJointInterface</hardwareInterface>
    </joint>
    <actuator name="motor11">
      <mechanicalReduction>1</mechanicalReduction>
      <hardwareInterface>hardware_interface/PositionJointInterface</hardwareInterface>
    </actuator>
  </transmission>
  
  <gazebo>

  <plugin name="differential_drive_controller" filename="libgazebo_ros_diff_drive.so">

    <!-- Plugin update rate in Hz -->
    <updateRate>${update_rate}</updateRate>

    <!-- Name of left joint, defaults to `left_joint` -->
    <leftJoint>joint_wheel2</leftJoint>

    <!-- Name of right joint, defaults to `right_joint` -->
    <rightJoint>joint_wheel1</rightJoint>

    <!-- The distance from the center of one wheel to the other, in meters, defaults to 0.34 m -->
    <wheelSeparation>4.23</wheelSeparation>

    <!-- Diameter of the wheels, in meters, defaults to 0.15 m -->
    <wheelDiameter>1.52</wheelDiameter>

    <!-- Wheel acceleration, in rad/s^2, defaults to 0.0 rad/s^2 -->
    <wheelAcceleration>10.0</wheelAcceleration>

    <!-- Maximum torque which the wheels can produce, in Nm, defaults to 5 Nm -->
    <wheelTorque>50</wheelTorque>

    <!-- Topic to receive geometry_msgs/Twist message commands, defaults to `cmd_vel` -->
    <commandTopic>cmd_vel</commandTopic>

    <!-- Topic to publish nav_msgs/Odometry messages, defaults to `odom` -->
    <odometryTopic>odom</odometryTopic>

    <!-- Odometry frame, defaults to `odom` -->
    <odometryFrame>odom</odometryFrame>

    <!-- Robot frame to calculate odometry from, defaults to `base_footprint` -->
    <robotBaseFrame>base_link</robotBaseFrame>

    <!-- Odometry source, 0 for ENCODER, 1 for WORLD, defaults to WORLD -->
    <odometrySource>1</odometrySource>

    <!-- Set to true to publish transforms for the wheel links, defaults to false -->
    <publishWheelTF>true</publishWheelTF>

    <!-- Set to true to publish transforms for the odometry, defaults to true -->
    <publishOdom>true</publishOdom>

    <!-- Set to true to publish sensor_msgs/JointState on /joint_states for the wheel joints, defaults to false -->
    <publishWheelJointState>true</publishWheelJointState>

    <!-- Set to true to swap right and left wheels, defaults to true -->
    <legacyMode>false</legacyMode>
  </plugin>
</gazebo>

</robot>